#VRML_SIM R2021a utf8
WorldInfo {
  physics "spherePhysics"
  basicTimeStep 8
  coordinateSystem "NUE"
  contactProperties [
    ContactProperties {
      material1 "sphere"
    }
    ContactProperties {
      material1 "robot"
    }
  ]
}
Viewpoint {
  orientation 0.07947184880624969 0.9936489328408293 0.0796619326378506 4.703628788786642
  position -0.9114633896584363 0.24907894708693148 0.011962443859263289
  follow "robot"
}
TexturedBackground {
}
TexturedBackgroundLight {
}
Group {
  children [
    DEF Floor RectangleArena {
      floorSize 50 50
      floorAppearance Parquetry {
        type "light strip"
      }
      wallHeight 1
    }
    Chair {
      translation -4 0 4
    }
    StoneFountain {
      translation 4 0 -4
    }
    PortraitPainting {
      translation 4 0.5 4
      rotation 0 1 0 -2.3561953071795863
    }
    WoodenPalletStack {
      translation -4 0 -4
    }
    SoccerBall {
      translation 0 0.11 4
    }
  ]
}
Robot {
  translation 0 0.1 0
  rotation 1 0 0 0
  children [
    DEF Controller Solid {
      children [
        BallJoint {
          jointParameters BallJointParameters {
            staticFriction 0.01
          }
          jointParameters2 JointParameters {
            staticFriction 0.01
          }
          jointParameters3 JointParameters {
            axis 0 1 0
            staticFriction 0.01
          }
          endPoint DEF Sphero Solid {
            rotation 0.5659091521127373 -0.3747180385214996 -0.7343930985253351 3.1052745527437557
            children [
              DEF HolllowSphere Shape {
                appearance PBRAppearance {
                  transparency 0.9
                  metalness 0
                }
                geometry Sphere {
                  radius 0.1
                  subdivision 2
                }
              }
            ]
            name "solid(1)"
            contactMaterial "sphere"
            boundingObject USE HolllowSphere
            physics Physics {
              density -1
              mass 0.05
            }
          }
        }
        DEF wheel0HJ HingeJoint {
          jointParameters HingeJointParameters {
            axis 0 0 -1
            anchor 0.09100000000000001 0 0
          }
          device [
            RotationalMotor {
              name "wheel0"
              maxVelocity 200
            }
          ]
          endPoint DEF wheel0Solid Solid {
            translation 0.09100000000000001 0 0
            rotation 1 -5.890192445936231e-16 1.570717985582995e-16 1.570000000000001
            children [
              Group {
                children [
                  DEF sr00 Solid {
                    translation 0.007000000000000001 0 0
                    rotation -2.9236047887014025e-49 1.256447388198122e-34 -1 6.283185307179586
                    children [
                      DEF r0 Transform {
                        rotation 1 0 0 1.5708
                        children [
                          DEF SMALL_WHEEL_SHAPE Shape {
                            appearance PBRAppearance {
                              baseColor 1 0.5 0.5
                              roughness 1
                            }
                            geometry Cylinder {
                              height 0.002
                              radius 0.001
                            }
                          }
                        ]
                      }
                    ]
                    name "sr00"
                    contactMaterial "wheel"
                    boundingObject USE r0
                    physics Physics {
                      density -1
                      mass 0.003
                    }
                  }
                  DEF sr01 Solid {
                    translation 0.006062177826491072 0 0.0034999999999999996
                    rotation -9.31641499045287e-15 1 3.3529040280388807e-14 5.7595865315813
                    children [
                      DEF r1 Transform {
                        rotation 1 0 0 1.5708
                        children [
                          USE SMALL_WHEEL_SHAPE
                        ]
                      }
                    ]
                    name "sr01"
                    contactMaterial "wheel"
                    boundingObject USE r1
                    physics Physics {
                      density -1
                      mass 0.003
                    }
                  }
                  DEF sr02 Solid {
                    translation 0.0035000000000000014 0 0.006062177826491071
                    rotation -1.620925615952744e-14 1 2.7366997557010516e-14 5.235987755983
                    children [
                      DEF r2 Transform {
                        rotation 1 0 0 1.5708
                        children [
                          USE SMALL_WHEEL_SHAPE
                        ]
                      }
                    ]
                    name "sr02"
                    contactMaterial "wheel"
                    boundingObject USE r2
                    physics Physics {
                      density -1
                      mass 0.003
                    }
                  }
                  DEF sr03 Solid {
                    translation 4.286263797015737e-19 0 0.007000000000000001
                    rotation -1.823504127604383e-14 1 1.8296483682599398e-14 4.712388980384693
                    children [
                      DEF r3 Transform {
                        rotation 1 0 0 1.5708
                        children [
                          USE SMALL_WHEEL_SHAPE
                        ]
                      }
                    ]
                    name "sr03"
                    contactMaterial "wheel"
                    boundingObject USE r3
                    physics Physics {
                      density -1
                      mass 0.003
                    }
                  }
                  DEF sr04 Solid {
                    translation -0.003499999999999999 0 0.006062177826491072
                    rotation -1.6056738431302777e-14 1 9.290313478590603e-15 4.188790204786395
                    children [
                      DEF r4 Transform {
                        rotation 1 0 0 1.5708
                        children [
                          USE SMALL_WHEEL_SHAPE
                        ]
                      }
                    ]
                    name "sr04"
                    contactMaterial "wheel"
                    boundingObject USE r4
                    physics Physics {
                      density -1
                      mass 0.003
                    }
                  }
                  DEF sr05 Solid {
                    translation -0.00606217782649107 0 0.0035000000000000027
                    rotation -9.367058757075123e-15 1 2.557611571187192e-15 3.665191429188093
                    children [
                      DEF r5 Transform {
                        rotation 1 0 0 1.5708
                        children [
                          USE SMALL_WHEEL_SHAPE
                        ]
                      }
                    ]
                    name "sr05"
                    contactMaterial "wheel"
                    boundingObject USE r5
                    physics Physics {
                      density -1
                      mass 0.003
                    }
                  }
                  DEF sr06 Solid {
                    translation -0.007000000000000001 0 8.572527594031474e-19
                    rotation -3.608224830031759e-16 1 -9.746148840128565e-19 3.141592653589793
                    children [
                      DEF r6 Transform {
                        rotation 1 0 0 1.5708
                        children [
                          USE SMALL_WHEEL_SHAPE
                        ]
                      }
                    ]
                    name "sr06"
                    contactMaterial "wheel"
                    boundingObject USE r6
                    physics Physics {
                      density -1
                      mass 0.003
                    }
                  }
                  DEF sr07 Solid {
                    translation -0.006062177826491073 0 -0.0034999999999999983
                    rotation 8.893385412459552e-15 0.9999999999999999 2.2736320541546435e-15 2.617993877991493
                    children [
                      DEF r7 Transform {
                        rotation 1 0 0 1.5708
                        children [
                          USE SMALL_WHEEL_SHAPE
                        ]
                      }
                    ]
                    name "sr07"
                    contactMaterial "wheel"
                    boundingObject USE r7
                    physics Physics {
                      density -1
                      mass 0.003
                    }
                  }
                  DEF sr08 Solid {
                    translation -0.003500000000000003 0 -0.00606217782649107
                    rotation 1.5636090343656377e-14 1 8.981838214316576e-15 2.09439510239319
                    children [
                      DEF r8 Transform {
                        rotation 1 0 0 1.5708
                        children [
                          USE SMALL_WHEEL_SHAPE
                        ]
                      }
                    ]
                    name "sr08"
                    contactMaterial "wheel"
                    boundingObject USE r8
                    physics Physics {
                      density -1
                      mass 0.003
                    }
                  }
                  DEF sr09 Solid {
                    translation -1.2858791391047211e-18 0 -0.007000000000000001
                    rotation 1.818150005391682e-14 1 1.824741829326554e-14 1.5707963267948917
                    children [
                      DEF r9 Transform {
                        rotation 1 0 0 1.5708
                        children [
                          USE SMALL_WHEEL_SHAPE
                        ]
                      }
                    ]
                    name "sr09"
                    contactMaterial "wheel"
                    boundingObject USE r9
                    physics Physics {
                      density -1
                      mass 0.003
                    }
                  }
                  DEF sr010 Solid {
                    translation 0.0034999999999999957 0 -0.0060621778264910746
                    rotation 1.5343629145015244e-14 1 2.7467611518617335e-14 1.0471975511965792
                    children [
                      DEF r10 Transform {
                        rotation 1 0 0 1.5708
                        children [
                          USE SMALL_WHEEL_SHAPE
                        ]
                      }
                    ]
                    name "sr010"
                    contactMaterial "wheel"
                    boundingObject USE r10
                    physics Physics {
                      density -1
                      mass 0.003
                    }
                  }
                  DEF sr011 Solid {
                    translation 0.006062177826491069 0 -0.003500000000000003
                    rotation 7.02501256249528e-15 1 3.1048293447049806e-14 0.5235987755982833
                    children [
                      DEF r11 Transform {
                        rotation 1 0 0 1.5708
                        children [
                          USE SMALL_WHEEL_SHAPE
                        ]
                      }
                    ]
                    name "sr011"
                    contactMaterial "wheel"
                    boundingObject USE r11
                    physics Physics {
                      density -1
                      mass 0.003
                    }
                  }
                ]
              }
              DEF wheelShape Shape {
                appearance PBRAppearance {
                }
                geometry DEF WheelGeo Cylinder {
                  height 0.002
                  radius 0.006
                }
              }
            ]
            name "wheel0"
            contactMaterial "wheel"
            boundingObject USE WheelGeo
            physics Physics {
              density -1
              mass 0.05
            }
          }
        }
        DEF wheel1HJ HingeJoint {
          jointParameters HingeJointParameters {
            axis 1.5 0 0.866025
            anchor -0.045500000000000006 0 0.0788084
          }
          device [
            RotationalMotor {
              name "wheel1"
              maxVelocity 200
            }
          ]
          endPoint DEF wheel1Solid Solid {
            translation -0.045500000000000006 0 0.0788084
            rotation 0.7744730964629543 0.44714205569288734 -0.4474990557373527 1.8228553071795845
            children [
              DEF wheelShape Shape {
                appearance PBRAppearance {
                }
                geometry DEF WheelGeo Cylinder {
                  height 0.002
                  radius 0.006
                }
              }
              Group {
                children [
                  DEF sr10 Solid {
                    translation 0.007000000000000001 0 0
                    rotation -2.9236047887014025e-49 1.256447388198122e-34 -1 6.283185307179586
                    children [
                      DEF r0 Transform {
                        rotation 1 0 0 1.5708
                        children [
                          DEF SMALL_WHEEL_SHAPE Shape {
                            appearance PBRAppearance {
                              baseColor 1 0.5 0.5
                              roughness 1
                            }
                            geometry Cylinder {
                              height 0.002
                              radius 0.001
                            }
                          }
                        ]
                      }
                    ]
                    name "sr10"
                    contactMaterial "wheel"
                    boundingObject USE r0
                    physics Physics {
                      density -1
                      mass 0.003
                    }
                  }
                  DEF sr11 Solid {
                    translation 0.006062177826491072 0 0.0034999999999999996
                    rotation -9.31641499045287e-15 1 3.3529040280388807e-14 5.7595865315813
                    children [
                      DEF r1 Transform {
                        rotation 1 0 0 1.5708
                        children [
                          USE SMALL_WHEEL_SHAPE
                        ]
                      }
                    ]
                    name "sr11"
                    contactMaterial "wheel"
                    boundingObject USE r1
                    physics Physics {
                      density -1
                      mass 0.003
                    }
                  }
                  DEF sr12 Solid {
                    translation 0.0035000000000000014 0 0.006062177826491071
                    rotation -1.620925615952744e-14 1 2.7366997557010516e-14 5.235987755983
                    children [
                      DEF r2 Transform {
                        rotation 1 0 0 1.5708
                        children [
                          USE SMALL_WHEEL_SHAPE
                        ]
                      }
                    ]
                    name "sr12"
                    contactMaterial "wheel"
                    boundingObject USE r2
                    physics Physics {
                      density -1
                      mass 0.003
                    }
                  }
                  DEF sr13 Solid {
                    translation 4.286263797015737e-19 0 0.007000000000000001
                    rotation -1.823504127604383e-14 1 1.8296483682599398e-14 4.712388980384693
                    children [
                      DEF r3 Transform {
                        rotation 1 0 0 1.5708
                        children [
                          USE SMALL_WHEEL_SHAPE
                        ]
                      }
                    ]
                    name "sr13"
                    contactMaterial "wheel"
                    boundingObject USE r3
                    physics Physics {
                      density -1
                      mass 0.003
                    }
                  }
                  DEF sr14 Solid {
                    translation -0.003499999999999999 0 0.006062177826491072
                    rotation -1.6056738431302777e-14 1 9.290313478590603e-15 4.188790204786395
                    children [
                      DEF r4 Transform {
                        rotation 1 0 0 1.5708
                        children [
                          USE SMALL_WHEEL_SHAPE
                        ]
                      }
                    ]
                    name "sr14"
                    contactMaterial "wheel"
                    boundingObject USE r4
                    physics Physics {
                      density -1
                      mass 0.003
                    }
                  }
                  DEF sr15 Solid {
                    translation -0.00606217782649107 0 0.0035000000000000027
                    rotation -9.367058757075123e-15 1 2.557611571187192e-15 3.665191429188093
                    children [
                      DEF r5 Transform {
                        rotation 1 0 0 1.5708
                        children [
                          USE SMALL_WHEEL_SHAPE
                        ]
                      }
                    ]
                    name "sr15"
                    contactMaterial "wheel"
                    boundingObject USE r5
                    physics Physics {
                      density -1
                      mass 0.003
                    }
                  }
                  DEF sr16 Solid {
                    translation -0.007000000000000001 0 8.572527594031474e-19
                    rotation -3.608224830031759e-16 1 -9.746148840128565e-19 3.141592653589793
                    children [
                      DEF r6 Transform {
                        rotation 1 0 0 1.5708
                        children [
                          USE SMALL_WHEEL_SHAPE
                        ]
                      }
                    ]
                    name "sr16"
                    contactMaterial "wheel"
                    boundingObject USE r6
                    physics Physics {
                      density -1
                      mass 0.003
                    }
                  }
                  DEF sr17 Solid {
                    translation -0.006062177826491073 0 -0.0034999999999999983
                    rotation 8.893385412459552e-15 0.9999999999999999 2.2736320541546435e-15 2.617993877991493
                    children [
                      DEF r7 Transform {
                        rotation 1 0 0 1.5708
                        children [
                          USE SMALL_WHEEL_SHAPE
                        ]
                      }
                    ]
                    name "sr17"
                    contactMaterial "wheel"
                    boundingObject USE r7
                    physics Physics {
                      density -1
                      mass 0.003
                    }
                  }
                  DEF sr18 Solid {
                    translation -0.003500000000000003 0 -0.00606217782649107
                    rotation 1.5636090343656377e-14 1 8.981838214316576e-15 2.09439510239319
                    children [
                      DEF r8 Transform {
                        rotation 1 0 0 1.5708
                        children [
                          USE SMALL_WHEEL_SHAPE
                        ]
                      }
                    ]
                    name "sr18"
                    contactMaterial "wheel"
                    boundingObject USE r8
                    physics Physics {
                      density -1
                      mass 0.003
                    }
                  }
                  DEF sr19 Solid {
                    translation -1.2858791391047211e-18 0 -0.007000000000000001
                    rotation 1.818150005391682e-14 1 1.824741829326554e-14 1.5707963267948917
                    children [
                      DEF r9 Transform {
                        rotation 1 0 0 1.5708
                        children [
                          USE SMALL_WHEEL_SHAPE
                        ]
                      }
                    ]
                    name "sr19"
                    contactMaterial "wheel"
                    boundingObject USE r9
                    physics Physics {
                      density -1
                      mass 0.003
                    }
                  }
                  DEF sr110 Solid {
                    translation 0.0034999999999999957 0 -0.0060621778264910746
                    rotation 1.5343629145015244e-14 1 2.7467611518617335e-14 1.0471975511965792
                    children [
                      DEF r10 Transform {
                        rotation 1 0 0 1.5708
                        children [
                          USE SMALL_WHEEL_SHAPE
                        ]
                      }
                    ]
                    name "sr110"
                    contactMaterial "wheel"
                    boundingObject USE r10
                    physics Physics {
                      density -1
                      mass 0.003
                    }
                  }
                  DEF sr111 Solid {
                    translation 0.006062177826491069 0 -0.003500000000000003
                    rotation 7.02501256249528e-15 1 3.1048293447049806e-14 0.5235987755982833
                    children [
                      DEF r11 Transform {
                        rotation 1 0 0 1.5708
                        children [
                          USE SMALL_WHEEL_SHAPE
                        ]
                      }
                    ]
                    name "sr111"
                    contactMaterial "wheel"
                    boundingObject USE r11
                    physics Physics {
                      density -1
                      mass 0.003
                    }
                  }
                ]
              }
            ]
            name "wheel1"
            contactMaterial "wheel"
            boundingObject DEF WheelGeo Cylinder {
              height 0.002
              radius 0.006
            }
            physics Physics {
              density -1
              mass 0.05
            }
          }
        }
        DEF wheel2HJ HingeJoint {
          jointParameters HingeJointParameters {
            axis -1.5 0 0.866025
            anchor -0.045500000000000006 0 -0.0788084
          }
          device [
            RotationalMotor {
              name "wheel2"
              maxVelocity 200
            }
          ]
          endPoint DEF wheel2Solid Solid {
            translation -0.045500000000000006 0 -0.0788084
            rotation 0.7744730964629541 -0.44714205569288673 0.44749905573735355 1.82286
            children [
              DEF wheelShape Shape {
                appearance PBRAppearance {
                }
                geometry DEF WheelGeo Cylinder {
                  height 0.002
                  radius 0.006
                }
              }
              Group {
                children [
                  DEF sr20 Solid {
                    translation 0.007000000000000001 0 0
                    rotation -2.9236047887014025e-49 1.256447388198122e-34 -1 6.283185307179586
                    children [
                      DEF r0 Transform {
                        rotation 1 0 0 1.5708
                        children [
                          DEF SMALL_WHEEL_SHAPE Shape {
                            appearance PBRAppearance {
                              baseColor 1 0.5 0.5
                              roughness 1
                            }
                            geometry Cylinder {
                              height 0.002
                              radius 0.001
                            }
                          }
                        ]
                      }
                    ]
                    name "sr20"
                    contactMaterial "wheel"
                    boundingObject USE r0
                    physics Physics {
                      density -1
                      mass 0.003
                    }
                  }
                  DEF sr21 Solid {
                    translation 0.006062177826491072 0 0.0034999999999999996
                    rotation -9.31641499045287e-15 1 3.3529040280388807e-14 5.7595865315813
                    children [
                      DEF r1 Transform {
                        rotation 1 0 0 1.5708
                        children [
                          USE SMALL_WHEEL_SHAPE
                        ]
                      }
                    ]
                    name "sr21"
                    contactMaterial "wheel"
                    boundingObject USE r1
                    physics Physics {
                      density -1
                      mass 0.003
                    }
                  }
                  DEF sr22 Solid {
                    translation 0.0035000000000000014 0 0.006062177826491071
                    rotation -1.620925615952744e-14 1 2.7366997557010516e-14 5.235987755983
                    children [
                      DEF r2 Transform {
                        rotation 1 0 0 1.5708
                        children [
                          USE SMALL_WHEEL_SHAPE
                        ]
                      }
                    ]
                    name "sr22"
                    contactMaterial "wheel"
                    boundingObject USE r2
                    physics Physics {
                      density -1
                      mass 0.003
                    }
                  }
                  DEF sr23 Solid {
                    translation 4.286263797015737e-19 0 0.007000000000000001
                    rotation -1.823504127604383e-14 1 1.8296483682599398e-14 4.712388980384693
                    children [
                      DEF r3 Transform {
                        rotation 1 0 0 1.5708
                        children [
                          USE SMALL_WHEEL_SHAPE
                        ]
                      }
                    ]
                    name "sr23"
                    contactMaterial "wheel"
                    boundingObject USE r3
                    physics Physics {
                      density -1
                      mass 0.003
                    }
                  }
                  DEF sr24 Solid {
                    translation -0.003499999999999999 0 0.006062177826491072
                    rotation -1.6056738431302777e-14 1 9.290313478590603e-15 4.188790204786395
                    children [
                      DEF r4 Transform {
                        rotation 1 0 0 1.5708
                        children [
                          USE SMALL_WHEEL_SHAPE
                        ]
                      }
                    ]
                    name "sr24"
                    contactMaterial "wheel"
                    boundingObject USE r4
                    physics Physics {
                      density -1
                      mass 0.003
                    }
                  }
                  DEF sr25 Solid {
                    translation -0.00606217782649107 0 0.0035000000000000027
                    rotation -9.367058757075123e-15 1 2.557611571187192e-15 3.665191429188093
                    children [
                      DEF r5 Transform {
                        rotation 1 0 0 1.5708
                        children [
                          USE SMALL_WHEEL_SHAPE
                        ]
                      }
                    ]
                    name "sr25"
                    contactMaterial "wheel"
                    boundingObject USE r5
                    physics Physics {
                      density -1
                      mass 0.003
                    }
                  }
                  DEF sr26 Solid {
                    translation -0.007000000000000001 0 8.572527594031474e-19
                    rotation -3.608224830031759e-16 1 -9.746148840128565e-19 3.141592653589793
                    children [
                      DEF r6 Transform {
                        rotation 1 0 0 1.5708
                        children [
                          USE SMALL_WHEEL_SHAPE
                        ]
                      }
                    ]
                    name "sr26"
                    contactMaterial "wheel"
                    boundingObject USE r6
                    physics Physics {
                      density -1
                      mass 0.003
                    }
                  }
                  DEF sr27 Solid {
                    translation -0.006062177826491073 0 -0.0034999999999999983
                    rotation 8.893385412459552e-15 0.9999999999999999 2.2736320541546435e-15 2.617993877991493
                    children [
                      DEF r7 Transform {
                        rotation 1 0 0 1.5708
                        children [
                          USE SMALL_WHEEL_SHAPE
                        ]
                      }
                    ]
                    name "sr27"
                    contactMaterial "wheel"
                    boundingObject USE r7
                    physics Physics {
                      density -1
                      mass 0.003
                    }
                  }
                  DEF sr28 Solid {
                    translation -0.003500000000000003 0 -0.00606217782649107
                    rotation 1.5636090343656377e-14 1 8.981838214316576e-15 2.09439510239319
                    children [
                      DEF r8 Transform {
                        rotation 1 0 0 1.5708
                        children [
                          USE SMALL_WHEEL_SHAPE
                        ]
                      }
                    ]
                    name "sr28"
                    contactMaterial "wheel"
                    boundingObject USE r8
                    physics Physics {
                      density -1
                      mass 0.003
                    }
                  }
                  DEF sr29 Solid {
                    translation -1.2858791391047211e-18 0 -0.007000000000000001
                    rotation 1.818150005391682e-14 1 1.824741829326554e-14 1.5707963267948917
                    children [
                      DEF r9 Transform {
                        rotation 1 0 0 1.5708
                        children [
                          USE SMALL_WHEEL_SHAPE
                        ]
                      }
                    ]
                    name "sr29"
                    contactMaterial "wheel"
                    boundingObject USE r9
                    physics Physics {
                      density -1
                      mass 0.003
                    }
                  }
                  DEF sr210 Solid {
                    translation 0.0034999999999999957 0 -0.0060621778264910746
                    rotation 1.5343629145015244e-14 1 2.7467611518617335e-14 1.0471975511965792
                    children [
                      DEF r10 Transform {
                        rotation 1 0 0 1.5708
                        children [
                          USE SMALL_WHEEL_SHAPE
                        ]
                      }
                    ]
                    name "sr210"
                    contactMaterial "wheel"
                    boundingObject USE r10
                    physics Physics {
                      density -1
                      mass 0.003
                    }
                  }
                  DEF sr211 Solid {
                    translation 0.006062177826491069 0 -0.003500000000000003
                    rotation 7.02501256249528e-15 1 3.1048293447049806e-14 0.5235987755982833
                    children [
                      DEF r11 Transform {
                        rotation 1 0 0 1.5708
                        children [
                          USE SMALL_WHEEL_SHAPE
                        ]
                      }
                    ]
                    name "sr211"
                    contactMaterial "wheel"
                    boundingObject USE r11
                    physics Physics {
                      density -1
                      mass 0.003
                    }
                  }
                ]
              }
            ]
            name "wheel2"
            contactMaterial "wheel"
            boundingObject DEF WheelGeo Cylinder {
              height 0.002
              radius 0.006
            }
            physics Physics {
              density -1
              mass 0.05
            }
          }
        }
        DEF CenterOfMass Transform {
          translation 0 -0.05 0
          children [
            DEF BodyShape Shape {
              appearance PBRAppearance {
              }
              geometry DEF BodyGeo Cylinder {
                height 0.02
                radius 0.04
              }
            }
          ]
        }
      ]
      boundingObject USE CenterOfMass
      physics Physics {
        density -1
        mass 0.5
      }
    }
    Accelerometer {
      yAxis FALSE
      resolution 0.1
    }
    Pen {
      inkColor 1 1 1
      inkDensity 1
    }
    Gyro {
      yAxis FALSE
      resolution 0.1
    }
    Receiver {
    }
    Emitter {
    }
    HingeJoint {
      jointParameters HingeJointParameters {
        axis 0 1 0
      }
      device [
        RotationalMotor {
          name "cameraMotor"
        }
      ]
      endPoint Camera {
        rotation 0 -1 0 1.5708
        children [
          DEF Dummy Solid {
          }
        ]
        locked TRUE
        fieldOfView 1.5
        width 256
        height 256
        antiAliasing TRUE
        lens Lens {
        }
      }
    }
  ]
  contactMaterial "robot"
  boundingObject USE CenterOfMass
  physics Physics {
    density -1
    mass 0.5
  }
  controller "Sphero"
}
